<?xml version="1.0" encoding="utf-8"?>
<robot name="kinova3" xmlns:xacro="http://www.ros.org/wiki/xacro">

  <xacro:arg name="mesh_prefix" default="model://" />
  <xacro:property name="mesh_prefix" value="$(arg mesh_prefix)" />

  <link name="world"/>
  <joint name="world_base_joint" type="fixed">
    <origin rpy="0 0 0" xyz="0 0 0"/>
    <parent link="world"/>
    <child link="base_link"/>
  </joint>

  <link name="base_link">
    <!-- <inertial>
          <origin xyz="-0.000648 -0.000166 0.084487" rpy="0 0 0" />
          <mass value="1.697" />
          <inertia ixx="0.004622" ixy="9E-06" ixz="6E-05" iyy="0.004495" iyz="9E-06" izz="0.002079" />
        </inertial> -->
    <visual>
      <origin rpy="0 0 0" xyz="0 0 0"/>
      <geometry>
        <mesh filename="${mesh_prefix}assets/arms/kinova3/meshes/base_link.STL"/>
      </geometry>
      <material name="">
        <color rgba="0.75294 0.75294 0.75294 1"/>
      </material>
    </visual>
    <collision>
      <origin rpy="0 0 0" xyz="0 0 0"/>
      <geometry>
        <mesh filename="${mesh_prefix}assets/arms/kinova3/meshes/base_link.STL"/>
      </geometry>
    </collision>`
  </link>
  <link name="base_link_dummy">
    <inertial>
      <origin rpy="0 0 0" xyz="-0.000648 -0.000166 0.084487"/>
      <mass value="1.697"/>
      <inertia ixx="0.004622" ixy="9E-06" ixz="6E-05" iyy="0.004495" iyz="9E-06" izz="0.002079"/>
    </inertial>
  </link>
  <joint name="base_dummy_joint" type="fixed">
    <origin rpy="0.0 0.0 0.0" xyz="0 0 0"/>
    <parent link="base_link"/>
    <child link="base_link_dummy"/>
  </joint>
  <link name="shoulder_link">
    <inertial>
      <origin rpy="0 0 0" xyz="-2.3E-05 -0.010364 -0.07336"/>
      <mass value="1.3773"/>
      <inertia ixx="0.00457" ixy="1E-06" ixz="2E-06" iyy="0.004831" iyz="0.000448" izz="0.001409"/>
    </inertial>
    <visual>
      <origin rpy="0 0 0" xyz="0 0 0"/>
      <geometry>
        <mesh filename="${mesh_prefix}assets/arms/kinova3/meshes/shoulder_link.STL"/>
      </geometry>
      <material name="">
        <color rgba="0.75294 0.75294 0.75294 1"/>
      </material>
    </visual>
    <collision>
      <origin rpy="0 0 0" xyz="0 0 0"/>
      <geometry>
        <mesh filename="${mesh_prefix}assets/arms/kinova3/meshes/shoulder_link.STL"/>
      </geometry>
    </collision>
  </link>
  <joint name="joint_1" type="revolute">
    <origin rpy="3.1416 2.7629E-18 -4.9305E-36" xyz="0 0 0.15643"/>
    <parent link="base_link"/>
    <child link="shoulder_link"/>
    <axis xyz="0 0 1"/>
    <limit effort="39" velocity="1.3963"  upper="3.17" lower="-3.17"/>
  </joint>
  <link name="half_arm_1_link">
    <inertial>
      <origin rpy="0 0 0" xyz="-4.4E-05 -0.09958 -0.013278"/>
      <mass value="1.1636"/>
      <inertia ixx="0.011088" ixy="5E-06" ixz="0" iyy="0.001072" iyz="-0.000691" izz="0.011255"/>
    </inertial>
    <visual>
      <origin rpy="0 0 0" xyz="0 0 0"/>
      <geometry>
        <mesh filename="${mesh_prefix}assets/arms/kinova3/meshes/half_arm_1_link.STL"/>
      </geometry>
      <material name="">
        <color rgba="0.75294 0.75294 0.75294 1"/>
      </material>
    </visual>
    <collision>
      <origin rpy="0 0 0" xyz="0 0 0"/>
      <geometry>
        <mesh filename="${mesh_prefix}assets/arms/kinova3/meshes/half_arm_1_link.STL"/>
      </geometry>
    </collision>
  </link>
  <joint name="joint_2" type="revolute">
    <origin rpy="1.5708 2.1343E-17 -1.1102E-16" xyz="0 0.005375 -0.12838"/>
    <parent link="shoulder_link"/>
    <child link="half_arm_1_link"/>
    <axis xyz="0 0 1"/>
    <limit effort="39" lower="-2.41" upper="2.41" velocity="1.3963"/>
  </joint>
  <link name="half_arm_2_link">
    <inertial>
      <origin rpy="0 0 0" xyz="-4.4E-05 -0.006641 -0.117892"/>
      <mass value="1.1636"/>
      <inertia ixx="0.010932" ixy="0" ixz="-7E-06" iyy="0.011127" iyz="0.000606" izz="0.001043"/>
    </inertial>
    <visual>
      <origin rpy="0 0 0" xyz="0 0 0"/>
      <geometry>
        <mesh filename="${mesh_prefix}assets/arms/kinova3/meshes/half_arm_2_link.STL"/>
      </geometry>
      <material name="">
        <color rgba="0.75294 0.75294 0.75294 1"/>
      </material>
    </visual>
    <collision>
      <origin rpy="0 0 0" xyz="0 0 0"/>
      <geometry>
        <mesh filename="${mesh_prefix}assets/arms/kinova3/meshes/half_arm_2_link.STL"/>
      </geometry>
    </collision>
  </link>
  <joint name="joint_3" type="revolute">
    <origin rpy="-1.5708 1.2326E-32 -2.9122E-16" xyz="0 -0.21038 -0.006375"/>
    <parent link="half_arm_1_link"/>
    <child link="half_arm_2_link"/>
    <axis xyz="0 0 1"/>
    <limit effort="39" velocity="1.3963"    upper="3.17" lower="-3.17"/>
  </joint>
  <link name="forearm_link">
    <inertial>
      <origin rpy="0 0 0" xyz="-1.8E-05 -0.075478 -0.015006"/>
      <mass value="0.9302"/>
      <inertia ixx="0.008147" ixy="-1E-06" ixz="0" iyy="0.000631" iyz="-0.0005" izz="0.008316"/>
    </inertial>
    <visual>
      <origin rpy="0 0 0" xyz="0 0 0"/>
      <geometry>
        <mesh filename="${mesh_prefix}assets/arms/kinova3/meshes/forearm_link.STL"/>
      </geometry>
      <material name="">
        <color rgba="0.75294 0.75294 0.75294 1"/>
      </material>
    </visual>
    <collision>
      <origin rpy="0 0 0" xyz="0 0 0"/>
      <geometry>
        <mesh filename="${mesh_prefix}assets/arms/kinova3/meshes/forearm_link.STL"/>
      </geometry>
    </collision>
  </link>
  <joint name="joint_4" type="revolute">
    <origin rpy="1.5708 -6.6954E-17 -1.6653E-16" xyz="0 0.006375 -0.21038"/>
    <parent link="half_arm_2_link"/>
    <child link="forearm_link"/>
    <axis xyz="0 0 1"/>
    <limit effort="39" lower="-2.66" upper="2.66" velocity="1.3963"/>
  </joint>
  <link name="spherical_wrist_1_link">
    <inertial>
      <origin rpy="0 0 0" xyz="1E-06 -0.009432 -0.063883"/>
      <mass value="0.6781"/>
      <inertia ixx="0.001596" ixy="0" ixz="0" iyy="0.001607" iyz="0.000256" izz="0.000399"/>
    </inertial>
    <visual>
      <origin rpy="0 0 0" xyz="0 0 0"/>
      <geometry>
        <mesh filename="${mesh_prefix}assets/arms/kinova3/meshes/spherical_wrist_1_link.STL"/>
      </geometry>
      <material name="">
        <color rgba="0.75294 0.75294 0.75294 1"/>
      </material>
    </visual>
    <collision>
      <origin rpy="0 0 0" xyz="0 0 0"/>
      <geometry>
        <mesh filename="${mesh_prefix}assets/arms/kinova3/meshes/spherical_wrist_1_link.STL"/>
      </geometry>
    </collision>
  </link>
  <joint name="joint_5" type="revolute">
    <origin rpy="-1.5708 2.2204E-16 -6.373E-17" xyz="0 -0.20843 -0.006375"/>
    <parent link="forearm_link"/>
    <child link="spherical_wrist_1_link"/>
    <axis xyz="0 0 1"/>
    <limit effort="9" velocity="1.2218"    upper="3.17" lower="-3.17"/>
  </joint>
  <link name="spherical_wrist_2_link">
    <inertial>
      <origin rpy="0 0 0" xyz="1E-06 -0.045483 -0.00965"/>
      <mass value="0.6781"/>
      <inertia ixx="0.001641" ixy="0" ixz="0" iyy="0.00041" iyz="-0.000278" izz="0.001641"/>
    </inertial>
    <visual>
      <origin rpy="0 0 0" xyz="0 0 0"/>
      <geometry>
        <mesh filename="${mesh_prefix}assets/arms/kinova3/meshes/spherical_wrist_2_link.STL"/>
      </geometry>
      <material name="">
        <color rgba="0.75294 0.75294 0.75294 1"/>
      </material>
    </visual>
    <collision>
      <origin rpy="0 0 0" xyz="0 0 0"/>
      <geometry>
        <mesh filename="${mesh_prefix}assets/arms/kinova3/meshes/spherical_wrist_2_link.STL"/>
      </geometry>
    </collision>
  </link>
  <joint name="joint_6" type="revolute">
    <origin rpy="1.5708 9.2076E-28 -8.2157E-15" xyz="0 0.00017505 -0.10593"/>
    <parent link="spherical_wrist_1_link"/>
    <child link="spherical_wrist_2_link"/>
    <axis xyz="0 0 1"/>
    <limit effort="9" lower="-2.23" upper="2.23" velocity="1.2218"/>
  </joint>
  <link name="bracelet_link">
    <inertial>
      <origin rpy="0 0 0" xyz="0.000281 0.011402 -0.029798"/>
      <mass value="0.5"/>
      <inertia ixx="0.000587" ixy="0.0" ixz="0.0" iyy="0.000369" iyz="-0.000118" izz="0.000609"/>
    </inertial>
    <visual>
      <origin rpy="0 0 0" xyz="0 0 0"/>
      <geometry>
        <mesh filename="${mesh_prefix}assets/arms/kinova3/meshes/bracelet_with_vision_link.STL"/>
      </geometry>
      <material name="">
        <color rgba="0.75294 0.75294 0.75294 1"/>
      </material>
    </visual>
    <collision>
      <origin rpy="0 0 0" xyz="0 0 0"/>
      <geometry>
        <mesh filename="${mesh_prefix}assets/arms/kinova3/meshes/bracelet_with_vision_link.STL"/>
      </geometry>
    </collision>
  </link>
  <joint name="joint_7" type="revolute">
    <origin rpy="-1.5708 -5.5511E-17 9.6396E-17" xyz="0 -0.10593 -0.00017505"/>
    <parent link="spherical_wrist_2_link"/>
    <child link="bracelet_link"/>
    <axis xyz="0 0 1"/>
    <limit effort="9" velocity="1.2218"   upper="3.17" lower="-3.17"/>
  </joint>
  <link name="end_effector_link">
    <inertial>
      <origin rpy="0 0 0" xyz="0 0 0"/>
      <mass value="0.01"/>
      <inertia ixx="0.0001" ixy="0.0" ixz="0.0" iyy="0.0001" iyz="0.0" izz="0.0001"/>
    </inertial>
  </link>
  <joint name="end_effector" type="fixed">
    <origin rpy="3.14159265358979 1.09937075168372E-32 0" xyz="0 0 -0.0615250000000001"/>
    <parent link="bracelet_link"/>
    <child link="end_effector_link"/>
    <axis xyz="0 0 0"/>
  </joint>

  <transmission name="joint_1_transmission">
    <type>transmission_interface/SimpleTransmission</type>
    <joint name="joint_1">
      <hardwareInterface>hardware_interface/EffortJointInterface</hardwareInterface>
    </joint>
    <actuator name="joint_1_motor">
      <mechanicalReduction>1</mechanicalReduction>
    </actuator>
  </transmission>

  <transmission name="joint_2_transmission">
    <type>transmission_interface/SimpleTransmission</type>
    <joint name="joint_2">
      <hardwareInterface>hardware_interface/EffortJointInterface</hardwareInterface>
    </joint>
    <actuator name="joint_2_motor">
      <mechanicalReduction>1</mechanicalReduction>
    </actuator>
  </transmission>

  <transmission name="joint_3_transmission">
    <type>transmission_interface/SimpleTransmission</type>
    <joint name="joint_3">
      <hardwareInterface>hardware_interface/EffortJointInterface</hardwareInterface>
    </joint>
    <actuator name="joint_3_motor">
      <mechanicalReduction>1</mechanicalReduction>
    </actuator>
  </transmission>

  <transmission name="joint_4_transmission">
    <type>transmission_interface/SimpleTransmission</type>
    <joint name="joint_4">
      <hardwareInterface>hardware_interface/EffortJointInterface</hardwareInterface>
    </joint>
    <actuator name="joint_4_motor">
      <mechanicalReduction>1</mechanicalReduction>
    </actuator>
  </transmission>

  <transmission name="joint_5_transmission">
    <type>transmission_interface/SimpleTransmission</type>
    <joint name="joint_5">
      <hardwareInterface>hardware_interface/EffortJointInterface</hardwareInterface>
    </joint>
    <actuator name="joint_5_motor">
      <mechanicalReduction>1</mechanicalReduction>
    </actuator>
  </transmission>

  <transmission name="joint_6_transmission">
    <type>transmission_interface/SimpleTransmission</type>
    <joint name="joint_6">
      <hardwareInterface>hardware_interface/EffortJointInterface</hardwareInterface>
    </joint>
    <actuator name="joint_6_motor">
      <mechanicalReduction>1</mechanicalReduction>
    </actuator>
  </transmission>

  <transmission name="joint_7_transmission">
    <type>transmission_interface/SimpleTransmission</type>
    <joint name="joint_7">
      <hardwareInterface>hardware_interface/EffortJointInterface</hardwareInterface>
    </joint>
    <actuator name="joint_7_motor">
      <mechanicalReduction>1</mechanicalReduction>
    </actuator>
  </transmission>

  <gazebo>
    <plugin name="gazebo_ros_control" filename="libgazebo_ros_control.so">
      <legacyModeNS>true</legacyModeNS>
      <!--robotParam>kinova_no_finger</robotParam-->
    </plugin>
  </gazebo>

</robot>
