<?xml version="1.0" encoding="utf-8"?>
<robot name="three_revolute_planar">
  <!-- Inertia box Ixx = 1/12 * (ly*2 + lh*2)-->

  <link name="base">
    <inertial>
      <origin xyz="0 0 0" rpy="0 0 0" />
      <mass value="1E-6" />
      <inertia ixx="0.0" ixy="0.0" ixz="0.0" iyy="0.0" iyz="0.0" izz="0.0" />
    </inertial>
  </link>

  <joint name="link_base_0_joint" type="revolute">
    <origin rpy="0 0 0" xyz="0 0 0"/>
    <parent link="base"/>
    <child link="link_0"/>
    <axis xyz="0 1 0"/>
    <limit effort="1000" lower="-30.14" upper="30.14" velocity="1.0"/>
  </joint>

  <link name="link_0">
    <inertial>
      <origin xyz="0.5 0.0 0.0" rpy="0 0 0" />
      <mass value="1.0" />
      <inertia ixx="0.001667" ixy="0.0" ixz="0.0" iyy="0.0841667" iyz="0.0" izz="0.084167" />
    </inertial>
    <visual>
      <origin xyz="0.5 0.0 0.0" rpy="0 0 0"/>
      <geometry>
        <box size="1.0 0.1 0.1"/>
      </geometry>
    </visual>
    <collision>
      <origin xyz="0.5 0.0 0.0" rpy="0 0 0"/>
      <geometry>
        <box size="1 0.1 0.1"/>
      </geometry>
    </collision>
  </link>

  <joint name="link_0_1_joint" type="revolute">
    <origin rpy="0 0 0" xyz="1.0 0.0 0.0"/>
    <parent link="link_0"/>
    <child link="link_1"/>
    <axis xyz="0 1 0"/>
    <limit effort="1000" lower="-30.14" upper="30.14" velocity="1.0"/>
  </joint>

  <link name="link_1">
    <inertial>
      <origin xyz="0.5 0.0 0.0" rpy="0 0 0" />
      <mass value="1.0" />
      <inertia ixx="0.001667" ixy="0.0" ixz="0.0" iyy="0.0841667" iyz="0.0" izz="0.084167" />
    </inertial>
    <visual>
      <origin xyz="0.5 0.0 0.0" rpy="0 0 0"/>
      <geometry>
        <box size="1 0.1 0.1"/>
      </geometry>
    </visual>
    <collision>
      <origin xyz="0.5 0.0 0.0" rpy="0 0 0"/>
      <geometry>
        <box size="1 0.1 0.1"/>
      </geometry>
    </collision>
  </link>

  <joint name="link_1_2_joint" type="revolute">
    <origin rpy="0 0 0" xyz="1.0 0.0 0.0"/>
    <parent link="link_1"/>
    <child link="link_2"/>
    <axis xyz="0 1 0"/>
    <limit effort="1000" lower="-30.14" upper="30.14" velocity="1.0"/>
  </joint>


  <link name="link_2">
    <inertial>
      <origin xyz="0.5 0.0 0.0" rpy="0 0 0" />
      <mass value="1.0" />
      <inertia ixx="0.001667" ixy="0.0" ixz="0.0" iyy="0.0841667" iyz="0.0" izz="0.084167" />
    </inertial>
    <visual>
      <origin xyz="0.5 0.0 0.0" rpy="0 0 0"/>
      <geometry>
        <box size="1 0.1 0.1"/>
      </geometry>
    </visual>
    <collision>
      <origin xyz="0.5 0.0 0.0" rpy="0 0 0"/>
      <geometry>
        <box size="1 0.1 0.1"/>
      </geometry>
    </collision>
  </link>

  <joint name="ee_joint" type="fixed">
    <origin rpy="0 0 0" xyz="1.0 0.0 0"/>
    <parent link="link_2"/>
    <child link="ee"/>
    <axis xyz="1 0 0"/>
  </joint>

  <link name="ee">
    <inertial>
      <origin xyz="0 0 0" rpy="0 0 0" />
      <mass value="1E-6" />
      <inertia ixx="1E-6" ixy="0" ixz="0" iyy="1E-6" iyz="0" izz="1E-6" />
    </inertial>
  </link>

</robot>

