<?xml version="1.0" ?>
<robot name="handwheel_valve">
   <link name="valve_base">
      <inertial>
        <mass value="1E-6" />
        <origin xyz="0.0 0.0 0.0" />
        <inertia ixx = "1E-6" ixy = "0.0" ixz = "0.0"
                iyx = "0.0" iyy = "1E-6" iyz = "0.0"
                izx = "0.0" izy = "0.0" izz = "1E-6" />
        </inertial>
    </link>


   <link name="valve">
    <contact>
      <friction_anchor/>
      <stiffness value="30000.0"/>
      <damping value="1000.0"/>
      <spinning_friction value="0.1"/>
      <lateral_friction value="1.0"/>
    </contact>
   <inertial>
      <mass value="1.0" />
<!--       Inertia of a torus radius = 0.12 and cross section radius 0.02-->
      <origin xyz="0.0 0.0 0.0" />
       <inertia ixx = "0.00745" ixy = "0.0" ixz = "0.0"
                iyx = "0.0" iyy = "0.0147" iyz = "0.0"
                izx = "0.0" izy = "0.0" izz = "0.00745" />
    </inertial>
    <collision name="collision">
      <geometry>
        <mesh filename="meshes/simple_valve_decomposed.obj" scale="0.005 0.005 0.005"/>
      </geometry>
    </collision>
    <visual name="visual">
      <geometry>
        <mesh filename="meshes/simple_valve_decomposed.obj" scale="0.005 0.005 0.005"/>
      </geometry>
    </visual>
  </link>

  <joint name="valve_joint" type="continuous">
    <origin xyz="0 0 0" rpy="-1.57 0 0"/>
    <axis xyz="0 1 0" rpy="0 0 0"/>
    <parent link="valve_base"/>
    <child link="valve"/>
    <dynamics damping="1.0" friction="10.0"/>
    <!-- <limit effort="30" velocity="1.0" lower="-3.14" upper="3.14"/> -->
   </joint>
</robot>

